Workbook

Sheet Ставки
A1: Ставки фирмы / Sätze und Zuschläge
A2: Жёлтые ячейки заполняет владелец (один раз). Пустая ячейка = «нет ставки» в расчёте. Проценты вводить как 15 %, а не 0,15.
A3: Параметр (RU) | B3: Значение | C3: Einheit | D3: Bezeichnung (DE) | E3: Пояснение
A4: Ставка подмастерья / рабочего | C4: €/h | D4: Stundensatz Geselle | E4: Kalkulationssatz за час (без MwSt)
A5: Ставка мастера | C5: €/h | D5: Stundensatz Meister | E5: Kalkulationssatz за час (без MwSt)
A6: Наценка на материал | C6: % | D6: Materialaufschlag | E6: Наценка на закупочную цену материала
A7: Накладные расходы | C7: % | D7: Gemeinkosten (BGK/AGK) | E7: На сумму Lohn + Material
A8: Риск | C8: % | D8: Wagnis | E8: На Selbstkosten
A9: Прибыль | C9: % | D9: Gewinn | E9: На Selbstkosten
A10: Транспорт за км | C10: €/km | D10: Fahrtkosten | E10: Цена за 1 км пути
A11: Почтовый индекс базы | C11: PLZ | D11: Firmensitz PLZ | E11: Откуда считается радиус (для агента 3)
A12: Рабочий радиус | C12: km | D12: Einsatzradius | E12: Дальше — заявки не берём / отдельно
A13: НДС | B13: 0.19 | C13: % | D13: MwSt (Regelsteuersatz) | E13: Установлен законом (§ 12 UStG), заполнено заранее
A15: Легенда:
A16: жёлтая ячейка | B16: вводит владелец

Sheet Позиции
A1: Каталог позиций Innenausbau / Leistungsverzeichnis (Stamm)
A2: Жёлтые столбцы E (часы на единицу) и F (материал €/ед.) заполняет владелец — только они идут в расчёт. Столбец G — ориентир, проверить по своему опыту; в формулах НЕ используется.
A4: Код | B4: Position (DE) | C4: Описание (RU) | D4: Einheit | E4: Zeit h/Einheit (владелец) | F4: Material €/Einheit (владелец, Einkauf netto) | G4: Ориентир h/ед. «ориентир, проверить по своему опыту» | H4: Примечание
A5: 01 Abbruch / Entsorgung
A6: AB-01 | B6: Abbruch Trockenbauwand | C6: Демонтаж ГКЛ-перегородки | D6: m² | G6: 0,3–0,5
A7: AB-02 | B7: Abbruch Wandfliesen inkl. Kleber | C7: Сбивка настенной плитки | D7: m² | G7: 0,5–0,8
A8: AB-03 | B8: Abbruch Bodenbelag (Teppich/PVC/Laminat) | C8: Снятие напольного покрытия | D8: m² | G8: 0,1–0,25
A9: AB-04 | B9: Abbruch Estrich | C9: Демонтаж стяжки | D9: m² | H9: сильно зависит от толщины
A10: EN-01 | B10: Entsorgung Bauschutt / Mischabfall | C10: Вывоз и утилизация мусора | D10: m³ | H10: в столбец F — цена контейнера/полигона за m³
A11: 02 Trockenbau
A12: TB-01 | B12: Trockenbau Wand CW/UW 75, 2-lagig beplankt, inkl. Dämmung | C12: Перегородка ГКЛ на профиле, 2 слоя, с утеплителем | D12: m² | G12: 0,8–1,2
A13: TB-02 | B13: Trockenbau Vorsatzschale | C13: Облицовка стены ГКЛ на профиле | D13: m² | G13: 0,6–0,9
A14: TB-03 | B14: Trockenbau Decke abgehängt (CD-Profil) | C14: Подвесной потолок ГКЛ | D14: m² | G14: 0,8–1,2
A15: TB-04 | B15: Trockenbau Dachschräge | C15: Обшивка мансардного ската | D15: m² | G15: 0,8–1,2
A16: TB-05 | B16: Türöffnung in Trockenbauwand (UA-Profil) | C16: Проём под дверь в ГКЛ-стене | D16: Stk | G16: 0,8–1,5
A17: TB-06 | B17: Revisionsklappe einbauen | C17: Установка ревизионного люка | D17: Stk | G17: 0,5–1,0
A18: 03 Spachteln / Maler
A19: SP-01 | B19: Spachteln Q2 | C19: Шпаклёвка Q2 (стандарт) | D19: m² | G19: 0,15–0,25
A20: SP-02 | B20: Spachteln Q3 | C20: Шпаклёвка Q3 (под гладкую покраску) | D20: m² | G20: 0,3–0,45
A21: MA-01 | B21: Abdecken / Abkleben | C21: Укрытие и оклейка | D21: m² | G21: 0,03–0,06 | H21: на m² пола
A22: MA-02 | B22: Grundierung / Tiefgrund | C22: Грунтовка | D22: m² | G22: 0,03–0,05
A23: MA-03 | B23: Malerarbeiten Wand, Dispersion 2x | C23: Покраска стен, 2 слоя | D23: m² | G23: 0,12–0,2
A24: MA-04 | B24: Malerarbeiten Decke, Dispersion 2x | C24: Покраска потолка, 2 слоя | D24: m² | G24: 0,15–0,25
A25: MA-05 | B25: Tapezieren Raufaser / Vlies | C25: Поклейка обоев | D25: m² | G25: 0,2–0,3
A26: 04 Boden
A27: BO-01 | B27: Untergrund ausgleichen (Ausgleichsmasse) | C27: Выравнивающая смесь | D27: m² | G27: 0,1–0,2
A28: BO-02 | B28: Trittschalldämmung verlegen | C28: Подложка | D28: m² | G28: 0,03–0,06
A29: BO-03 | B29: Bodenbelag Vinyl (Klick) verlegen | C29: Укладка винила (клик) | D29: m² | G29: 0,25–0,4
A30: BO-04 | B30: Bodenbelag Laminat verlegen | C30: Укладка ламината | D30: m² | G30: 0,25–0,4
A31: BO-05 | B31: Sockelleisten montieren | C31: Плинтус | D31: lfm | G31: 0,08–0,15
A32: BO-06 | B32: Estrich (Zementestrich) einbringen | C32: Цементная стяжка | D32: m² | H32: часто субподряд — уточнить
A33: 05 Fliesen
A34: FL-01 | B34: Abdichtung Nassbereich (Verbundabdichtung) | C34: Гидроизоляция мокрой зоны | D34: m² | G34: 0,2–0,4
A35: FL-02 | B35: Fliesen Wand verlegen | C35: Укладка настенной плитки | D35: m² | G35: 1,0–1,5 | H35: формат плитки сильно влияет
A36: FL-03 | B36: Fliesen Boden verlegen | C36: Укладка напольной плитки | D36: m² | G36: 0,8–1,3 | H36: формат плитки сильно влияет
A37: FL-04 | B37: Silikonfugen | C37: Силиконовые швы | D37: lfm | G37: 0,05–0,1
A38: 06 Türen
A39: TU-01 | B39: Innentür inkl. Zarge montieren | C39: Монтаж межкомнатной двери с коробкой | D39: Stk | G39: 1,5–2,5
A40: TU-02 | B40: Innentür demontieren | C40: Демонтаж двери | D40: Stk | G40: 0,3–0,6
A41: 07 Sonstiges
...

Sheet Расчёт
A1: Расчёт / Kalkulation
A2: Объект / Bauvorhaben:
A3: Выбрать позицию в столбце B (список), ввести количество (D) и тип ставки (E). Остальное считается само. «нет ставки» = не заполнена ставка/норма/цена на листах «Ставки» или «Позиции».
A5: Nr | B5: Position (из списка «Позиции») | C5: Einheit | D5: Menge | E5: Lohnart Geselle/Meister | F5: Zeit h/Einheit | G5: Stundensatz €/h | H5: Lohn € = Menge×h×Satz | I5: Material €/Einheit | J5: Material € inkl. Aufschlag = Menge×Preis×(1+Aufschlag) | K5: Einzelkosten € (Lohn+Material) | L5: Gemeinkosten € | M5: Selbstkosten € | N5: Wagnis € | O5: Gewinn € | P5: Netto € (Angebotspreis) | Q5: Einheitspreis € (netto)
A6: 1 | B6: Trockenbau Wand CW/UW 75, 2-lagig beplankt, inkl. Dämmung | C6: =IF($B6="","",IFERROR(INDEX('Позиции'!$D$5:$D$53,MATCH($B6,'Позиции'!$B$5:$B$53,0)),"")) | D6: 25 | E6: Geselle | F6: =IF($B6="","",IFERROR(IF(INDEX('Позиции'!$E$5:$E$53,MATCH($B6,'Позиции'!$B$5:$B$53,0))="","нет ставки",INDEX('Позиции'!$E$5:$E$53,MATCH($B6,'Позиции'!$B$5:$B$53,0))),"нет ставки")) | G6: =IF($B6="","",IF($E6="Meister",IF(ISBLANK('Ставки'!$B$5),"нет ставки",'Ставки'!$B$5),IF(ISBLANK('Ставки'!$B$4),"нет ставки",'Ставки'!$B$4))) | H6: =IF($B6="","",IF(AND(ISNUMBER($D6),ISNUMBER($F6),ISNUMBER($G6)),$D6*$F6*$G6,"нет ставки")) | I6: =IF($B6="","",IFERROR(IF(INDEX('Позиции'!$F$5:$F$53,MATCH($B6,'Позиции'!$B$5:$B$53,0))="","нет ставки",INDEX('Позиции'!$F$5:$F$53,MATCH($B6,'Позиции'!$B$5:$B$53,0))),"нет ставки")) | J6: =IF($B6="","",IF(AND(ISNUMBER($D6),ISNUMBER($I6),NOT(ISBLANK('Ставки'!$B$6))),$D6*$I6*(1+'Ставки'!$B$6),"нет ставки")) | K6: =IF($B6="","",IF(AND(ISNUMBER($H6),ISNUMBER($J6)),$H6+$J6,"нет ставки")) | L6: =IF($B6="","",IF(AND(ISNUMBER($K6),NOT(ISBLANK('Ставки'!$B$7))),$K6*'Ставки'!$B$7,"нет ставки")) | M6: =IF($B6="","",IF(AND(ISNUMBER($K6),ISNUMBER($L6)),$K6+$L6,"нет ставки")) | N6: =IF($B6="","",IF(AND(ISNUMBER($M6),NOT(ISBLANK('Ставки'!$B$8))),$M6*'Ставки'!$B$8,"нет ставки")) | O6: =IF($B6="","",IF(AND(ISNUMBER($M6),NOT(ISBLANK('Ставки'!$B$9))),$M6*'Ставки'!$B$9,"нет ставки")) | P6: =IF($B6="","",IF(AND(ISNUMBER($M6),ISNUMBER($N6),ISNUMBER($O6)),$M6+$N6+$O6,"нет ставки")) | Q6: =IF($B6="","",IF(AND(ISNUMBER($P6),ISNUMBER($D6)),IF($D6=0,"нет ставки",$P6/$D6),"нет ставки"))
A7: 2 | C7: =IF($B7="","",IFERROR(INDEX('Позиции'!$D$5:$D$53,MATCH($B7,'Позиции'!$B$5:$B$53,0)),"")) | E7: Geselle | F7: =IF($B7="","",IFERROR(IF(INDEX('Позиции'!$E$5:$E$53,MATCH($B7,'Позиции'!$B$5:$B$53,0))="","нет ставки",INDEX('Позиции'!$E$5:$E$53,MATCH($B7,'Позиции'!$B$5:$B$53,0))),"нет ставки")) | G7: =IF($B7="","",IF($E7="Meister",IF(ISBLANK('Ставки'!$B$5),"нет ставки",'Ставки'!$B$5),IF(ISBLANK('Ставки'!$B$4),"нет ставки",'Ставки'!$B$4))) | H7: =IF($B7="","",IF(AND(ISNUMBER($D7),ISNUMBER($F7),ISNUMBER($G7)),$D7*$F7*$G7,"нет ставки")) | I7: =IF($B7="","",IFERROR(IF(INDEX('Позиции'!$F$5:$F$53,MATCH($B7,'Позиции'!$B$5:$B$53,0))="","нет ставки",INDEX('Позиции'!$F$5:$F$53,MATCH($B7,'Позиции'!$B$5:$B$53,0))),"нет ставки")) | J7: =IF($B7="","",IF(AND(ISNUMBER($D7),ISNUMBER($I7),NOT(ISBLANK('Ставки'!$B$6))),$D7*$I7*(1+'Ставки'!$B$6),"нет ставки")) | K7: =IF($B7="","",IF(AND(ISNUMBER($H7),ISNUMBER($J7)),$H7+$J7,"нет ставки")) | L7: =IF($B7="","",IF(AND(ISNUMBER($K7),NOT(ISBLANK('Ставки'!$B$7))),$K7*'Ставки'!$B$7,"нет ставки")) | M7: =IF($B7="","",IF(AND(ISNUMBER($K7),ISNUMBER($L7)),$K7+$L7,"нет ставки")) | N7: =IF($B7="","",IF(AND(ISNUMBER($M7),NOT(ISBLANK('Ставки'!$B$8))),$M7*'Ставки'!$B$8,"нет ставки")) | O7: =IF($B7="","",IF(AND(ISNUMBER($M7),NOT(ISBLANK('Ставки'!$B$9))),$M7*'Ставки'!$B$9,"нет ставки")) | P7: =IF($B7="","",IF(AND(ISNUMBER($M7),ISNUMBER($N7),ISNUMBER($O7)),$M7+$N7+$O7,"нет ставки")) | Q7: =IF($B7="","",IF(AND(ISNUMBER($P7),ISNUMBER($D7)),IF($D7=0,"нет ставки",$P7/$D7),"нет ставки"))
A8: 3 | C8: =IF($B8="","",IFERROR(INDEX('Позиции'!$D$5:$D$53,MATCH($B8,'Позиции'!$B$5:$B$53,0)),"")) | E8: Geselle | F8: =IF($B8="","",IFERROR(IF(INDEX('Позиции'!$E$5:$E$53,MATCH($B8,'Позиции'!$B$5:$B$53,0))="","нет ставки",INDEX('Позиции'!$E$5:$E$53,MATCH($B8,'Позиции'!$B$5:$B$53,0))),"нет ставки")) | G8: =IF($B8="","",IF($E8="Meister",IF(ISBLANK('Ставки'!$B$5),"нет ставки",'Ставки'!$B$5),IF(ISBLANK('Ставки'!$B$4),"нет ставки",'Ставки'!$B$4))) | H8: =IF($B8="","",IF(AND(ISNUMBER($D8),ISNUMBER($F8),ISNUMBER($G8)),$D8*$F8*$G8,"нет ставки")) | I8: =IF($B8="","",IFERROR(IF(INDEX('Позиции'!$F$5:$F$53,MATCH($B8,'Позиции'!$B$5:$B$53,0))="","нет ставки",INDEX('Позиции'!$F$5:$F$53,MATCH($B8,'Позиции'!$B$5:$B$53,0))),"нет ставки")) | J8: =IF($B8="","",IF(AND(ISNUMBER($D8),ISNUMBER($I8),NOT(ISBLANK('Ставки'!$B$6))),$D8*$I8*(1+'Ставки'!$B$6),"нет ставки")) | K8: =IF($B8="","",IF(AND(ISNUMBER($H8),ISNUMBER($J8)),$H8+$J8,"нет ставки")) | L8: =IF($B8="","",IF(AND(ISNUMBER($K8),NOT(ISBLANK('Ставки'!$B$7))),$K8*'Ставки'!$B$7,"нет ставки")) | M8: =IF($B8="","",IF(AND(ISNUMBER($K8),ISNUMBER($L8)),$K8+$L8,"нет ставки")) | N8: =IF($B8="","",IF(AND(ISNUMBER($M8),NOT(ISBLANK('Ставки'!$B$8))),$M8*'Ставки'!$B$8,"нет ставки")) | O8: =IF($B8="","",IF(AND(ISNUMBER($M8),NOT(ISBLANK('Ставки'!$B$9))),$M8*'Ставки'!$B$9,"нет ставки")) | P8: =IF($B8="","",IF(AND(ISNUMBER($M8),ISNUMBER($N8),ISNUMBER($O8)),$M8+$N8+$O8,"нет ставки")) | Q8: =IF($B8="","",IF(AND(ISNUMBER($P8),ISNUMBER($D8)),IF($D8=0,"нет ставки",$P8/$D8),"нет ставки"))
A9: 4 | C9: =IF($B9="","",IFERROR(INDEX('Позиции'!$D$5:$D$53,MATCH($B9,'Позиции'!$B$5:$B$53,0)),"")) | E9: Geselle | F9: =IF($B9="","",IFERROR(IF(INDEX('Позиции'!$E$5:$E$53,MATCH($B9,'Позиции'!$B$5:$B$53,0))="","нет ставки",INDEX('Позиции'!$E$5:$E$53,MATCH($B9,'Позиции'!$B$5:$B$53,0))),"нет ставки")) | G9: =IF($B9="","",IF($E9="Meister",IF(ISBLANK('Ставки'!$B$5),"нет ставки",'Ставки'!$B$5),IF(ISBLANK('Ставки'!$B$4),"нет ставки",'Ставки'!$B$4))) | H9: =IF($B9="","",IF(AND(ISNUMBER($D9),ISNUMBER($F9),ISNUMBER($G9)),$D9*$F9*$G9,"нет ставки")) | I9: =IF($B9="","",IFERROR(IF(INDEX('Позиции'!$F$5:$F$53,MATCH($B9,'Позиции'!$B$5:$B$53,0))="","нет ставки",INDEX('Позиции'!$F$5:$F$53,MATCH($B9,'Позиции'!$B$5:$B$53,0))),"нет ставки")) | J9: =IF($B9="","",IF(AND(ISNUMBER($D9),ISNUMBER($I9),NOT(ISBLANK('Ставки'!$B$6))),$D9*$I9*(1+'Ставки'!$B$6),"нет ставки")) | K9: =IF($B9="","",IF(AND(ISNUMBER($H9),ISNUMBER($J9)),$H9+$J9,"нет ставки")) | L9: =IF($B9="","",IF(AND(ISNUMBER($K9),NOT(ISBLANK('Ставки'!$B$7))),$K9*'Ставки'!$B$7,"нет ставки")) | M9: =IF($B9="","",IF(AND(ISNUMBER($K9),ISNUMBER($L9)),$K9+$L9,"нет ставки")) | N9: =IF($B9="","",IF(AND(ISNUMBER($M9),NOT(ISBLANK('Ставки'!$B$8))),$M9*'Ставки'!$B$8,"нет ставки")) | O9: =IF($B9="","",IF(AND(ISNUMBER($M9),NOT(ISBLANK('Ставки'!$B$9))),$M9*'Ставки'!$B$9,"нет ставки")) | P9: =IF($B9="","",IF(AND(ISNUMBER($M9),ISNUMBER($N9),ISNUMBER($O9)),$M9+$N9+$O9,"нет ставки")) | Q9: =IF($B9="","",IF(AND(ISNUMBER($P9),ISNUMBER($D9)),IF($D9=0,"нет ставки",$P9/$D9),"нет ставки"))
A10: 5 | C10: =IF($B10="","",IFERROR(INDEX('Позиции'!$D$5:$D$53,MATCH($B10,'Позиции'!$B$5:$B$53,0)),"")) | E10: Geselle | F10: =IF($B10="","",IFERROR(IF(INDEX('Позиции'!$E$5:$E$53,MATCH($B10,'Позиции'!$B$5:$B$53,0))="","нет ставки",INDEX('Позиции'!$E$5:$E$53,MATCH($B10,'Позиции'!$B$5:$B$53,0))),"нет ставки")) | G10: =IF($B10="","",IF($E10="Meister",IF(ISBLANK('Ставки'!$B$5),"нет ставки",'Ставки'!$B$5),IF(ISBLANK('Ставки'!$B$4),"нет ставки",'Ставки'!$B$4))) | H10: =IF($B10="","",IF(AND(ISNUMBER($D10),ISNUMBER($F10),ISNUMBER($G10)),$D10*$F10*$G10,"нет ставки")) | I10: =IF($B10="","",IFERROR(IF(INDEX('Позиции'!$F$5:$F$53,MATCH($B10,'Позиции'!$B$5:$B$53,0))="","нет ставки",INDEX('Позиции'!$F$5:$F$53,MATCH($B10,'Позиции'!$B$5:$B$53,0))),"нет ставки")) | J10: =IF($B10="","",IF(AND(ISNUMBER($D10),ISNUMBER($I10),NOT(ISBLANK('Ставки'!$B$6))),$D10*$I10*(1+'Ставки'!$B$6),"нет ставки")) | K10: =IF($B10="","",IF(AND(ISNUMBER($H10),ISNUMBER($J10)),$H10+$J10,"нет ставки")) | L10: =IF($B10="","",IF(AND(ISNUMBER($K10),NOT(ISBLANK('Ставки'!$B$7))),$K10*'Ставки'!$B$7,"нет ставки")) | M10: =IF($B10="","",IF(AND(ISNUMBER($K10),ISNUMBER($L10)),$K10+$L10,"нет ставки")) | N10: =IF($B10="","",IF(AND(ISNUMBER($M10),NOT(ISBLANK('Ставки'!$B$8))),$M10*'Ставки'!$B$8,"нет ставки")) | O10: =IF($B10="","",IF(AND(ISNUMBER($M10),NOT(ISBLANK('Ставки'!$B$9))),$M10*'Ставки'!$B$9,"нет ставки")) | P10: =IF($B10="","",IF(AND(ISNUMBER($M10),ISNUMBER($N10),ISNUMBER($O10)),$M10+$N10+$O10,"нет ставки")) | Q10: =IF($B10="","",IF(AND(ISNUMBER($P10),ISNUMBER($D10)),IF($D10=0,"нет ставки",$P10/$D10),"нет ставки"))
A11: 6 | C11: =IF($B11="","",IFERROR(INDEX('Позиции'!$D$5:$D$53,MATCH($B11,'Позиции'!$B$5:$B$53,0)),"")) | E11: Geselle | F11: =IF($B11="","",IFERROR(IF(INDEX('Позиции'!$E$5:$E$53,MATCH($B11,'Позиции'!$B$5:$B$53,0))="","нет ставки",INDEX('Позиции'!$E$5:$E$53,MATCH($B11,'Позиции'!$B$5:$B$53,0))),"нет ставки")) | G11: =IF($B11="","",IF($E11="Meister",IF(ISBLANK('Ставки'!$B$5),"нет ставки",'Ставки'!$B$5),IF(ISBLANK('Ставки'!$B$4),"нет ставки",'Ставки'!$B$4))) | H11: =IF($B11="","",IF(AND(ISNUMBER($D11),ISNUMBER($F11),ISNUMBER($G11)),$D11*$F11*$G11,"нет ставки")) | I11: =IF($B11="","",IFERROR(IF(INDEX('Позиции'!$F$5:$F$53,MATCH($B11,'Позиции'!$B$5:$B$53,0))="","нет ставки",INDEX('Позиции'!$F$5:$F$53,MATCH($B11,'Позиции'!$B$5:$B$53,0))),"нет ставки")) | J11: =IF($B11="","",IF(AND(ISNUMBER($D11),ISNUMBER($I11),NOT(ISBLANK('Ставки'!$B$6))),$D11*$I11*(1+'Ставки'!$B$6),"нет ставки")) | K11: =IF($B11="","",IF(AND(ISNUMBER($H11),ISNUMBER($J11)),$H11+$J11,"нет ставки")) | L11: =IF($B11="","",IF(AND(ISNUMBER($K11),NOT(ISBLANK('Ставки'!$B$7))),$K11*'Ставки'!$B$7,"нет ставки")) | M11: =IF($B11="","",IF(AND(ISNUMBER($K11),ISNUMBER($L11)),$K11+$L11,"нет ставки")) | N11: =IF($B11="","",IF(AND(ISNUMBER($M11),NOT(ISBLANK('Ставки'!$B$8))),$M11*'Ставки'!$B$8,"нет ставки")) | O11: =IF($B11="","",IF(AND(ISNUMBER($M11),NOT(ISBLANK('Ставки'!$B$9))),$M11*'Ставки'!$B$9,"нет ставки")) | P11: =IF($B11="","",IF(AND(ISNUMBER($M11),ISNUMBER($N11),ISNUMBER($O11)),$M11+$N11+$O11,"нет ставки")) | Q11: =IF($B11="","",IF(AND(ISNUMBER($P11),ISNUMBER($D11)),IF($D11=0,"нет ставки",$P11/$D11),"нет ставки"))
A12: 7 | C12: =IF($B12="","",IFERROR(INDEX('Позиции'!$D$5:$D$53,MATCH($B12,'Позиции'!$B$5:$B$53,0)),"")) | E12: Geselle | F12: =IF($B12="","",IFERROR(IF(INDEX('Позиции'!$E$5:$E$53,MATCH($B12,'Позиции'!$B$5:$B$53,0))="","нет ставки",INDEX('Позиции'!$E$5:$E$53,MATCH($B12,'Позиции'!$B$5:$B$53,0))),"нет ставки")) | G12: =IF($B12="","",IF($E12="Meister",IF(ISBLANK('Ставки'!$B$5),"нет ставки",'Ставки'!$B$5),IF(ISBLANK('Ставки'!$B$4),"нет ставки",'Ставки'!$B$4))) | H12: =IF($B12="","",IF(AND(ISNUMBER($D12),ISNUMBER($F12),ISNUMBER($G12)),$D12*$F12*$G12,"нет ставки")) | I12: =IF($B12="","",IFERROR(IF(INDEX('Позиции'!$F$5:$F$53,MATCH($B12,'Позиции'!$B$5:$B$53,0))="","нет ставки",INDEX('Позиции'!$F$5:$F$53,MATCH($B12,'Позиции'!$B$5:$B$53,0))),"нет ставки")) | J12: =IF($B12="","",IF(AND(ISNUMBER($D12),ISNUMBER($I12),NOT(ISBLANK('Ставки'!$B$6))),$D12*$I12*(1+'Ставки'!$B$6),"нет ставки")) | K12: =IF($B12="","",IF(AND(ISNUMBER($H12),ISNUMBER($J12)),$H12+$J12,"нет ставки")) | L12: =IF($B12="","",IF(AND(ISNUMBER($K12),NOT(ISBLANK('Ставки'!$B$7))),$K12*'Ставки'!$B$7,"нет ставки")) | M12: =IF($B12="","",IF(AND(ISNUMBER($K12),ISNUMBER($L12)),$K12+$L12,"нет ставки")) | N12: =IF($B12="","",IF(AND(ISNUMBER($M12),NOT(ISBLANK('Ставки'!$B$8))),$M12*'Ставки'!$B$8,"нет ставки")) | O12: =IF($B12="","",IF(AND(ISNUMBER($M12),NOT(ISBLANK('Ставки'!$B$9))),$M12*'Ставки'!$B$9,"нет ставки")) | P12: =IF($B12="","",IF(AND(ISNUMBER($M12),ISNUMBER($N12),ISNUMBER($O12)),$M12+$N12+$O12,"нет ставки")) | Q12: =IF($B12="","",IF(AND(ISNUMBER($P12),ISNUMBER($D12)),IF($D12=0,"нет ставки",$P12/$D12),"нет ставки"))
A13: 8 | C13: =IF($B13="","",IFERROR(INDEX('Позиции'!$D$5:$D$53,MATCH($B13,'Позиции'!$B$5:$B$53,0)),"")) | E13: Geselle | F13: =IF($B13="","",IFERROR(IF(INDEX('Позиции'!$E$5:$E$53,MATCH($B13,'Позиции'!$B$5:$B$53,0))="","нет ставки",INDEX('Позиции'!$E$5:$E$53,MATCH($B13,'Позиции'!$B$5:$B$53,0))),"нет ставки")) | G13: =IF($B13="","",IF($E13="Meister",IF(ISBLANK('Ставки'!$B$5),"нет ставки",'Ставки'!$B$5),IF(ISBLANK('Ставки'!$B$4),"нет ставки",'Ставки'!$B$4))) | H13: =IF($B13="","",IF(AND(ISNUMBER($D13),ISNUMBER($F13),ISNUMBER($G13)),$D13*$F13*$G13,"нет ставки")) | I13: =IF($B13="","",IFERROR(IF(INDEX('Позиции'!$F$5:$F$53,MATCH($B13,'Позиции'!$B$5:$B$53,0))="","нет ставки",INDEX('Позиции'!$F$5:$F$53,MATCH($B13,'Позиции'!$B$5:$B$53,0))),"нет ставки")) | J13: =IF($B13="","",IF(AND(ISNUMBER($D13),ISNUMBER($I13),NOT(ISBLANK('Ставки'!$B$6))),$D13*$I13*(1+'Ставки'!$B$6),"нет ставки")) | K13: =IF($B13="","",IF(AND(ISNUMBER($H13),ISNUMBER($J13)),$H13+$J13,"нет ставки")) | L13: =IF($B13="","",IF(AND(ISNUMBER($K13),NOT(ISBLANK('Ставки'!$B$7))),$K13*'Ставки'!$B$7,"нет ставки")) | M13: =IF($B13="","",IF(AND(ISNUMBER($K13),ISNUMBER($L13)),$K13+$L13,"нет ставки")) | N13: =IF($B13="","",IF(AND(ISNUMBER($M13),NOT(ISBLANK('Ставки'!$B$8))),$M13*'Ставки'!$B$8,"нет ставки")) | O13: =IF($B13="","",IF(AND(ISNUMBER($M13),NOT(ISBLANK('Ставки'!$B$9))),$M13*'Ставки'!$B$9,"нет ставки")) | P13: =IF($B13="","",IF(AND(ISNUMBER($M13),ISNUMBER($N13),ISNUMBER($O13)),$M13+$N13+$O13,"нет ставки")) | Q13: =IF($B13="","",IF(AND(ISNUMBER($P13),ISNUMBER($D13)),IF($D13=0,"нет ставки",$P13/$D13),"нет ставки"))
A14: 9 | C14: =IF($B14="","",IFERROR(INDEX('Позиции'!$D$5:$D$53,MATCH($B14,'Позиции'!$B$5:$B$53,0)),"")) | E14: Geselle | F14: =IF($B14="","",IFERROR(IF(INDEX('Позиции'!$E$5:$E$53,MATCH($B14,'Позиции'!$B$5:$B$53,0))="","нет ставки",INDEX('Позиции'!$E$5:$E$53,MATCH($B14,'Позиции'!$B$5:$B$53,0))),"нет ставки")) | G14: =IF($B14="","",IF($E14="Meister",IF(ISBLANK('Ставки'!$B$5),"нет ставки",'Ставки'!$B$5),IF(ISBLANK('Ставки'!$B$4),"нет ставки",'Ставки'!$B$4))) | H14: =IF($B14="","",IF(AND(ISNUMBER($D14),ISNUMBER($F14),ISNUMBER($G14)),$D14*$F14*$G14,"нет ставки")) | I14: =IF($B14="","",IFERROR(IF(INDEX('Позиции'!$F$5:$F$53,MATCH($B14,'Позиции'!$B$5:$B$53,0))="","нет ставки",INDEX('Позиции'!$F$5:$F$53,MATCH($B14,'Позиции'!$B$5:$B$53,0))),"нет ставки")) | J14: =IF($B14="","",IF(AND(ISNUMBER($D14),ISNUMBER($I14),NOT(ISBLANK('Ставки'!$B$6))),$D14*$I14*(1+'Ставки'!$B$6),"нет ставки")) | K14: =IF($B14="","",IF(AND(ISNUMBER($H14),ISNUMBER($J14)),$H14+$J14,"нет ставки")) | L14: =IF($B14="","",IF(AND(ISNUMBER($K14),NOT(ISBLANK('Ставки'!$B$7))),$K14*'Ставки'!$B$7,"нет ставки")) | M14: =IF($B14="","",IF(AND(ISNUMBER($K14),ISNUMBER($L14)),$K14+$L14,"нет ставки")) | N14: =IF($B14="","",IF(AND(ISNUMBER($M14),NOT(ISBLANK('Ставки'!$B$8))),$M14*'Ставки'!$B$8,"нет ставки")) | O14: =IF($B14="","",IF(AND(ISNUMBER($M14),NOT(ISBLANK('Ставки'!$B$9))),$M14*'Ставки'!$B$9,"нет ставки")) | P14: =IF($B14="","",IF(AND(ISNUMBER($M14),ISNUMBER($N14),ISNUMBER($O14)),$M14+$N14+$O14,"нет ставки")) | Q14: =IF($B14="","",IF(AND(ISNUMBER($P14),ISNUMBER($D14)),IF($D14=0,"нет ставки",$P14/$D14),"нет ставки"))
A15: 10 | C15: =IF($B15="","",IFERROR(INDEX('Позиции'!$D$5:$D$53,MATCH($B15,'Позиции'!$B$5:$B$53,0)),"")) | E15: Geselle | F15: =IF($B15="","",IFERROR(IF(INDEX('Позиции'!$E$5:$E$53,MATCH($B15,'Позиции'!$B$5:$B$53,0))="","нет ставки",INDEX('Позиции'!$E$5:$E$53,MATCH($B15,'Позиции'!$B$5:$B$53,0))),"нет ставки")) | G15: =IF($B15="","",IF($E15="Meister",IF(ISBLANK('Ставки'!$B$5),"нет ставки",'Ставки'!$B$5),IF(ISBLANK('Ставки'!$B$4),"нет ставки",'Ставки'!$B$4))) | H15: =IF($B15="","",IF(AND(ISNUMBER($D15),ISNUMBER($F15),ISNUMBER($G15)),$D15*$F15*$G15,"нет ставки")) | I15: =IF($B15="","",IFERROR(IF(INDEX('Позиции'!$F$5:$F$53,MATCH($B15,'Позиции'!$B$5:$B$53,0))="","нет ставки",INDEX('Позиции'!$F$5:$F$53,MATCH($B15,'Позиции'!$B$5:$B$53,0))),"нет ставки")) | J15: =IF($B15="","",IF(AND(ISNUMBER($D15),ISNUMBER($I15),NOT(ISBLANK('Ставки'!$B$6))),$D15*$I15*(1+'Ставки'!$B$6),"нет ставки")) | K15: =IF($B15="","",IF(AND(ISNUMBER($H15),ISNUMBER($J15)),$H15+$J15,"нет ставки")) | L15: =IF($B15="","",IF(AND(ISNUMBER($K15),NOT(ISBLANK('Ставки'!$B$7))),$K15*'Ставки'!$B$7,"нет ставки")) | M15: =IF($B15="","",IF(AND(ISNUMBER($K15),ISNUMBER($L15)),$K15+$L15,"нет ставки")) | N15: =IF($B15="","",IF(AND(ISNUMBER($M15),NOT(ISBLANK('Ставки'!$B$8))),$M15*'Ставки'!$B$8,"нет ставки")) | O15: =IF($B15="","",IF(AND(ISNUMBER($M15),NOT(ISBLANK('Ставки'!$B$9))),$M15*'Ставки'!$B$9,"нет ставки")) | P15: =IF($B15="","",IF(AND(ISNUMBER($M15),ISNUMBER($N15),ISNUMBER($O15)),$M15+$N15+$O15,"нет ставки")) | Q15: =IF($B15="","",IF(AND(ISNUMBER($P15),ISNUMBER($D15)),IF($D15=0,"нет ставки",$P15/$D15),"нет ставки"))
A16: 11 | C16: =IF($B16="","",IFERROR(INDEX('Позиции'!$D$5:$D$53,MATCH($B16,'Позиции'!$B$5:$B$53,0)),"")) | E16: Geselle | F16: =IF($B16="","",IFERROR(IF(INDEX('Позиции'!$E$5:$E$53,MATCH($B16,'Позиции'!$B$5:$B$53,0))="","нет ставки",INDEX('Позиции'!$E$5:$E$53,MATCH($B16,'Позиции'!$B$5:$B$53,0))),"нет ставки")) | G16: =IF($B16="","",IF($E16="Meister",IF(ISBLANK('Ставки'!$B$5),"нет ставки",'Ставки'!$B$5),IF(ISBLANK('Ставки'!$B$4),"нет ставки",'Ставки'!$B$4))) | H16: =IF($B16="","",IF(AND(ISNUMBER($D16),ISNUMBER($F16),ISNUMBER($G16)),$D16*$F16*$G16,"нет ставки")) | I16: =IF($B16="","",IFERROR(IF(INDEX('Позиции'!$F$5:$F$53,MATCH($B16,'Позиции'!$B$5:$B$53,0))="","нет ставки",INDEX('Позиции'!$F$5:$F$53,MATCH($B16,'Позиции'!$B$5:$B$53,0))),"нет ставки")) | J16: =IF($B16="","",IF(AND(ISNUMBER($D16),ISNUMBER($I16),NOT(ISBLANK('Ставки'!$B$6))),$D16*$I16*(1+'Ставки'!$B$6),"нет ставки")) | K16: =IF($B16="","",IF(AND(ISNUMBER($H16),ISNUMBER($J16)),$H16+$J16,"нет ставки")) | L16: =IF($B16="","",IF(AND(ISNUMBER($K16),NOT(ISBLANK('Ставки'!$B$7))),$K16*'Ставки'!$B$7,"нет ставки")) | M16: =IF($B16="","",IF(AND(ISNUMBER($K16),ISNUMBER($L16)),$K16+$L16,"нет ставки")) | N16: =IF($B16="","",IF(AND(ISNUMBER($M16),NOT(ISBLANK('Ставки'!$B$8))),$M16*'Ставки'!$B$8,"нет ставки")) | O16: =IF($B16="","",IF(AND(ISNUMBER($M16),NOT(ISBLANK('Ставки'!$B$9))),$M16*'Ставки'!$B$9,"нет ставки")) | P16: =IF($B16="","",IF(AND(ISNUMBER($M16),ISNUMBER($N16),ISNUMBER($O16)),$M16+$N16+$O16,"нет ставки")) | Q16: =IF($B16="","",IF(AND(ISNUMBER($P16),ISNUMBER($D16)),IF($D16=0,"нет ставки",$P16/$D16),"нет ставки"))
A17: 12 | C17: =IF($B17="","",IFERROR(INDEX('Позиции'!$D$5:$D$53,MATCH($B17,'Позиции'!$B$5:$B$53,0)),"")) | E17: Geselle | F17: =IF($B17="","",IFERROR(IF(INDEX('Позиции'!$E$5:$E$53,MATCH($B17,'Позиции'!$B$5:$B$53,0))="","нет ставки",INDEX('Позиции'!$E$5:$E$53,MATCH($B17,'Позиции'!$B$5:$B$53,0))),"нет ставки")) | G17: =IF($B17="","",IF($E17="Meister",IF(ISBLANK('Ставки'!$B$5),"нет ставки",'Ставки'!$B$5),IF(ISBLANK('Ставки'!$B$4),"нет ставки",'Ставки'!$B$4))) | H17: =IF($B17="","",IF(AND(ISNUMBER($D17),ISNUMBER($F17),ISNUMBER($G17)),$D17*$F17*$G17,"нет ставки")) | I17: =IF($B17="","",IFERROR(IF(INDEX('Позиции'!$F$5:$F$53,MATCH($B17,'Позиции'!$B$5:$B$53,0))="","нет ставки",INDEX('Позиции'!$F$5:$F$53,MATCH($B17,'Позиции'!$B$5:$B$53,0))),"нет ставки")) | J17: =IF($B17="","",IF(AND(ISNUMBER($D17),ISNUMBER($I17),NOT(ISBLANK('Ставки'!$B$6))),$D17*$I17*(1+'Ставки'!$B$6),"нет ставки")) | K17: =IF($B17="","",IF(AND(ISNUMBER($H17),ISNUMBER($J17)),$H17+$J17,"нет ставки")) | L17: =IF($B17="","",IF(AND(ISNUMBER($K17),NOT(ISBLANK('Ставки'!$B$7))),$K17*'Ставки'!$B$7,"нет ставки")) | M17: =IF($B17="","",IF(AND(ISNUMBER($K17),ISNUMBER($L17)),$K17+$L17,"нет ставки")) | N17: =IF($B17="","",IF(AND(ISNUMBER($M17),NOT(ISBLANK('Ставки'!$B$8))),$M17*'Ставки'!$B$8,"нет ставки")) | O17: =IF($B17="","",IF(AND(ISNUMBER($M17),NOT(ISBLANK('Ставки'!$B$9))),$M17*'Ставки'!$B$9,"нет ставки")) | P17: =IF($B17="","",IF(AND(ISNUMBER($M17),ISNUMBER($N17),ISNUMBER($O17)),$M17+$N17+$O17,"нет ставки")) | Q17: =IF($B17="","",IF(AND(ISNUMBER($P17),ISNUMBER($D17)),IF($D17=0,"нет ставки",$P17/$D17),"нет ставки"))
A18: 13 | C18: =IF($B18="","",IFERROR(INDEX('Позиции'!$D$5:$D$53,MATCH($B18,'Позиции'!$B$5:$B$53,0)),"")) | E18: Geselle | F18: =IF($B18="","",IFERROR(IF(INDEX('Позиции'!$E$5:$E$53,MATCH($B18,'Позиции'!$B$5:$B$53,0))="","нет ставки",INDEX('Позиции'!$E$5:$E$53,MATCH($B18,'Позиции'!$B$5:$B$53,0))),"нет ставки")) | G18: =IF($B18="","",IF($E18="Meister",IF(ISBLANK('Ставки'!$B$5),"нет ставки",'Ставки'!$B$5),IF(ISBLANK('Ставки'!$B$4),"нет ставки",'Ставки'!$B$4))) | H18: =IF($B18="","",IF(AND(ISNUMBER($D18),ISNUMBER($F18),ISNUMBER($G18)),$D18*$F18*$G18,"нет ставки")) | I18: =IF($B18="","",IFERROR(IF(INDEX('Позиции'!$F$5:$F$53,MATCH($B18,'Позиции'!$B$5:$B$53,0))="","нет ставки",INDEX('Позиции'!$F$5:$F$53,MATCH($B18,'Позиции'!$B$5:$B$53,0))),"нет ставки")) | J18: =IF($B18="","",IF(AND(ISNUMBER($D18),ISNUMBER($I18),NOT(ISBLANK('Ставки'!$B$6))),$D18*$I18*(1+'Ставки'!$B$6),"нет ставки")) | K18: =IF($B18="","",IF(AND(ISNUMBER($H18),ISNUMBER($J18)),$H18+$J18,"нет ставки")) | L18: =IF($B18="","",IF(AND(ISNUMBER($K18),NOT(ISBLANK('Ставки'!$B$7))),$K18*'Ставки'!$B$7,"нет ставки")) | M18: =IF($B18="","",IF(AND(ISNUMBER($K18),ISNUMBER($L18)),$K18+$L18,"нет ставки")) | N18: =IF($B18="","",IF(AND(ISNUMBER($M18),NOT(ISBLANK('Ставки'!$B$8))),$M18*'Ставки'!$B$8,"нет ставки")) | O18: =IF($B18="","",IF(AND(ISNUMBER($M18),NOT(ISBLANK('Ставки'!$B$9))),$M18*'Ставки'!$B$9,"нет ставки")) | P18: =IF($B18="","",IF(AND(ISNUMBER($M18),ISNUMBER($N18),ISNUMBER($O18)),$M18+$N18+$O18,"нет ставки")) | Q18: =IF($B18="","",IF(AND(ISNUMBER($P18),ISNUMBER($D18)),IF($D18=0,"нет ставки",$P18/$D18),"нет ставки"))
... A30: 25 | C30: =IF($B30="","",IFERROR(INDEX('Позиции'!$D$5:$D$53,MATCH($B30,'Позиции'!$B$5:$B$53,0)),"")) | E30: Geselle | F30: =IF($B30="","",IFERROR(IF(INDEX('Позиции'!$E$5:$E$53,MATCH($B30,'Позиции'!$B$5:$B$53,0))="","нет ставки",INDEX('Позиции'!$E$5:$E$53,MATCH($B30,'Позиции'!$B$5:$B$53,0))),"нет ставки")) | G30: =IF($B30="","",IF($E30="Meister",IF(ISBLANK('Ставки'!$B$5),"нет ставки",'Ставки'!$B$5),IF(ISBLANK('Ставки'!$B$4),"нет ставки",'Ставки'!$B$4))) | H30: =IF($B30="","",IF(AND(ISNUMBER($D30),ISNUMBER($F30),ISNUMBER($G30)),$D30*$F30*$G30,"нет ставки")) | I30: =IF($B30="","",IFERROR(IF(INDEX('Позиции'!$F$5:$F$53,MATCH($B30,'Позиции'!$B$5:$B$53,0))="","нет ставки",INDEX('Позиции'!$F$5:$F$53,MATCH($B30,'Позиции'!$B$5:$B$53,0))),"нет ставки")) | J30: =IF($B30="","",IF(AND(ISNUMBER($D30),ISNUMBER($I30),NOT(ISBLANK('Ставки'!$B$6))),$D30*$I30*(1+'Ставки'!$B$6),"нет ставки")) | K30: =IF($B30="","",IF(AND(ISNUMBER($H30),ISNUMBER($J30)),$H30+$J30,"нет ставки")) | L30: =IF($B30="","",IF(AND(ISNUMBER($K30),NOT(ISBLANK('Ставки'!$B$7))),$K30*'Ставки'!$B$7,"нет ставки")) | M30: =IF($B30="","",IF(AND(ISNUMBER($K30),ISNUMBER($L30)),$K30+$L30,"нет ставки")) | N30: =IF($B30="","",IF(AND(ISNUMBER($M30),NOT(ISBLANK('Ставки'!$B$8))),$M30*'Ставки'!$B$8,"нет ставки")) | O30: =IF($B30="","",IF(AND(ISNUMBER($M30),NOT(ISBLANK('Ставки'!$B$9))),$M30*'Ставки'!$B$9,"нет ставки")) | P30: =IF($B30="","",IF(AND(ISNUMBER($M30),ISNUMBER($N30),ISNUMBER($O30)),$M30+$N30+$O30,"нет ставки")) | Q30: =IF($B30="","",IF(AND(ISNUMBER($P30),ISNUMBER($D30)),IF($D30=0,"нет ставки",$P30/$D30),"нет ставки"))
A32: Fahrtkosten / транспорт
B33: Entfernung einfach, km (от базы до объекта)
B34: Anzahl Fahrten (туда-обратно)
B35: Fahrtkosten € = km × 2 × Fahrten × €/km | D35: =IF(AND(ISBLANK(D33),ISBLANK(D34)),0,IF(AND(ISNUMBER(D33),ISNUMBER(D34),NOT(ISBLANK('Ставки'!$B$10))),D33*2*D34*'Ставки'!$B$10,"нет ставки")) | E35: пусто = без транспорта
A37: Итог / Zusammenfassung
B38: Lohn gesamt | D38: =IF(OR(COUNTIF(P6:P30,"нет ставки")>0,COUNTA(B6:B30)=0,NOT(ISNUMBER($D$35))),"нет ставки",SUM(H6:H30)) | E38: работа
B39: Material inkl. Aufschlag gesamt | D39: =IF(OR(COUNTIF(P6:P30,"нет ставки")>0,COUNTA(B6:B30)=0,NOT(ISNUMBER($D$35))),"нет ставки",SUM(J6:J30)) | E39: материал с наценкой
B40: Gemeinkosten gesamt | D40: =IF(OR(COUNTIF(P6:P30,"нет ставки")>0,COUNTA(B6:B30)=0,NOT(ISNUMBER($D$35))),"нет ставки",SUM(L6:L30)) | E40: накладные
B41: Fahrtkosten | D41: =$D$35 | E41: транспорт
B42: Selbstkosten gesamt | D42: =IF(OR(COUNTIF(P6:P30,"нет ставки")>0,COUNTA(B6:B30)=0,NOT(ISNUMBER($D$35))),"нет ставки",SUM(M6:M30)+$D$35) | E42: себестоимость = Lohn + Material + GK + Fahrt
B43: Wagnis | D43: =IF(OR(COUNTIF(P6:P30,"нет ставки")>0,COUNTA(B6:B30)=0,NOT(ISNUMBER($D$35))),"нет ставки",SUM(N6:N30)+$D$35*'Ставки'!$B$8) | E43: риск
B44: Gewinn (geplant) | D44: =IF(OR(COUNTIF(P6:P30,"нет ставки")>0,COUNTA(B6:B30)=0,NOT(ISNUMBER($D$35))),"нет ставки",SUM(O6:O30)+$D$35*'Ставки'!$B$9) | E44: плановая прибыль
B45: Angebotssumme netto | D45: =IF(OR(COUNTIF(P6:P30,"нет ставки")>0,COUNTA(B6:B30)=0,NOT(ISNUMBER($D$35))),"нет ставки",SUM(P6:P30)+$D$35*(1+'Ставки'!$B$8+'Ставки'!$B$9)) | E45: Netto
B46: MwSt | D46: =IF(ISNUMBER(D45),D45*'Ставки'!$B$13,"нет ставки") | E46: НДС
B47: Angebotssumme brutto | D47: =IF(ISNUMBER(D45),D45+D46,"нет ставки") | E47: Brutto
B48: Profit € (Netto − Selbstkosten) | D48: =IF(ISNUMBER(D45),D45-D42,"нет ставки") | E48: прибыль € (Wagnis + Gewinn, если риск не случился)
B49: Marge % (Profit / Netto) | D49: =IF(ISNUMBER(D45),IF(D45=0,"нет ставки",D48/D45),"нет ставки") | E49: маржа %
B51: Fahrtkosten в Angebot идут отдельной строкой «Anfahrt» по цене Fahrt × (1 + Wagnis + Gewinn). Gemeinkosten считаются от Lohn + Material; Wagnis и Gewinn — от Selbstkosten.

Sheet Angebot
A1: [Firma]
A2: [Adresse] · [PLZ Ort] · Tel. [Telefon] · [E-Mail]
A3: USt-IdNr.: [USt-IdNr] · Steuernummer: [Steuernummer]
A5: An: [Kunde Name] | E5: Datum: | F5: =TODAY()
A6: [Kunde Adresse] | E6: Angebots-Nr.: | F6: [Nr.]
A8: ANGEBOT
A9: ='Расчёт'!C2 | B9: ← Bauvorhaben (из листа «Расчёт», C2)
A10: Sehr geehrte Damen und Herren,
A11: vielen Dank für Ihre Anfrage. Gerne bieten wir Ihnen folgende Leistungen an:
A13: Pos. | B13: Bezeichnung | C13: Menge | D13: Einheit | E13: Einheitspreis € | F13: Gesamtpreis €
A14: =IF('Расчёт'!B6="","",'Расчёт'!A6) | B14: =IF('Расчёт'!B6="","",'Расчёт'!B6) | C14: =IF('Расчёт'!B6="","",'Расчёт'!D6) | D14: =IF('Расчёт'!B6="","",'Расчёт'!C6) | E14: =IF('Расчёт'!B6="","",'Расчёт'!Q6) | F14: =IF('Расчёт'!B6="","",'Расчёт'!P6)
A15: =IF('Расчёт'!B7="","",'Расчёт'!A7) | B15: =IF('Расчёт'!B7="","",'Расчёт'!B7) | C15: =IF('Расчёт'!B7="","",'Расчёт'!D7) | D15: =IF('Расчёт'!B7="","",'Расчёт'!C7) | E15: =IF('Расчёт'!B7="","",'Расчёт'!Q7) | F15: =IF('Расчёт'!B7="","",'Расчёт'!P7)
A16: =IF('Расчёт'!B8="","",'Расчёт'!A8) | B16: =IF('Расчёт'!B8="","",'Расчёт'!B8) | C16: =IF('Расчёт'!B8="","",'Расчёт'!D8) | D16: =IF('Расчёт'!B8="","",'Расчёт'!C8) | E16: =IF('Расчёт'!B8="","",'Расчёт'!Q8) | F16: =IF('Расчёт'!B8="","",'Расчёт'!P8)
A17: =IF('Расчёт'!B9="","",'Расчёт'!A9) | B17: =IF('Расчёт'!B9="","",'Расчёт'!B9) | C17: =IF('Расчёт'!B9="","",'Расчёт'!D9) | D17: =IF('Расчёт'!B9="","",'Расчёт'!C9) | E17: =IF('Расчёт'!B9="","",'Расчёт'!Q9) | F17: =IF('Расчёт'!B9="","",'Расчёт'!P9)
A18: =IF('Расчёт'!B10="","",'Расчёт'!A10) | B18: =IF('Расчёт'!B10="","",'Расчёт'!B10) | C18: =IF('Расчёт'!B10="","",'Расчёт'!D10) | D18: =IF('Расчёт'!B10="","",'Расчёт'!C10) | E18: =IF('Расчёт'!B10="","",'Расчёт'!Q10) | F18: =IF('Расчёт'!B10="","",'Расчёт'!P10)
A19: =IF('Расчёт'!B11="","",'Расчёт'!A11) | B19: =IF('Расчёт'!B11="","",'Расчёт'!B11) | C19: =IF('Расчёт'!B11="","",'Расчёт'!D11) | D19: =IF('Расчёт'!B11="","",'Расчёт'!C11) | E19: =IF('Расчёт'!B11="","",'Расчёт'!Q11) | F19: =IF('Расчёт'!B11="","",'Расчёт'!P11)
A20: =IF('Расчёт'!B12="","",'Расчёт'!A12) | B20: =IF('Расчёт'!B12="","",'Расчёт'!B12) | C20: =IF('Расчёт'!B12="","",'Расчёт'!D12) | D20: =IF('Расчёт'!B12="","",'Расчёт'!C12) | E20: =IF('Расчёт'!B12="","",'Расчёт'!Q12) | F20: =IF('Расчёт'!B12="","",'Расчёт'!P12)
A21: =IF('Расчёт'!B13="","",'Расчёт'!A13) | B21: =IF('Расчёт'!B13="","",'Расчёт'!B13) | C21: =IF('Расчёт'!B13="","",'Расчёт'!D13) | D21: =IF('Расчёт'!B13="","",'Расчёт'!C13) | E21: =IF('Расчёт'!B13="","",'Расчёт'!Q13) | F21: =IF('Расчёт'!B13="","",'Расчёт'!P13)
A22: =IF('Расчёт'!B14="","",'Расчёт'!A14) | B22: =IF('Расчёт'!B14="","",'Расчёт'!B14) | C22: =IF('Расчёт'!B14="","",'Расчёт'!D14) | D22: =IF('Расчёт'!B14="","",'Расчёт'!C14) | E22: =IF('Расчёт'!B14="","",'Расчёт'!Q14) | F22: =IF('Расчёт'!B14="","",'Расчёт'!P14)
A23: =IF('Расчёт'!B15="","",'Расчёт'!A15) | B23: =IF('Расчёт'!B15="","",'Расчёт'!B15) | C23: =IF('Расчёт'!B15="","",'Расчёт'!D15) | D23: =IF('Расчёт'!B15="","",'Расчёт'!C15) | E23: =IF('Расчёт'!B15="","",'Расчёт'!Q15) | F23: =IF('Расчёт'!B15="","",'Расчёт'!P15)
A24: =IF('Расчёт'!B16="","",'Расчёт'!A16) | B24: =IF('Расчёт'!B16="","",'Расчёт'!B16) | C24: =IF('Расчёт'!B16="","",'Расчёт'!D16) | D24: =IF('Расчёт'!B16="","",'Расчёт'!C16) | E24: =IF('Расчёт'!B16="","",'Расчёт'!Q16) | F24: =IF('Расчёт'!B16="","",'Расчёт'!P16)
A25: =IF('Расчёт'!B17="","",'Расчёт'!A17) | B25: =IF('Расчёт'!B17="","",'Расчёт'!B17) | C25: =IF('Расчёт'!B17="","",'Расчёт'!D17) | D25: =IF('Расчёт'!B17="","",'Расчёт'!C17) | E25: =IF('Расчёт'!B17="","",'Расчёт'!Q17) | F25: =IF('Расчёт'!B17="","",'Расчёт'!P17)
... A38: =IF('Расчёт'!B30="","",'Расчёт'!A30) | B38: =IF('Расчёт'!B30="","",'Расчёт'!B30) | C38: =IF('Расчёт'!B30="","",'Расчёт'!D30) | D38: =IF('Расчёт'!B30="","",'Расчёт'!C30) | E38: =IF('Расчёт'!B30="","",'Расчёт'!Q30) | F38: =IF('Расчёт'!B30="","",'Расчёт'!P30)
A39: =IF('Расчёт'!$D$35=0,"","F") | B39: =IF('Расчёт'!$D$35=0,"","Anfahrt / Fahrtkosten") | C39: =IF('Расчёт'!$D$35=0,"",1) | D39: =IF('Расчёт'!$D$35=0,"","psch") | E39: =F39 | F39: =IF('Расчёт'!$D$35=0,"",IF(AND(ISNUMBER('Расчёт'!$D$35),NOT(ISBLANK('Ставки'!$B$8)),NOT(ISBLANK('Ставки'!$B$9))),'Расчёт'!$D$35*(1+'Ставки'!$B$8+'Ставки'!$B$9),"нет ставки"))
E41: Summe netto | F41: ='Расчёт'!D45
E42: ="zzgl. MwSt "&TEXT('Ставки'!B13*100,"0")&" %" | F42: ='Расчёт'!D46
E43: Gesamtbetrag brutto | F43: ='Расчёт'!D47
A46: Dieses Angebot ist 30 Tage ab Angebotsdatum gültig.
A47: Zahlungsbedingungen: [Zahlungsbedingungen, z. B. Abschlagszahlungen / Zahlungsziel]
A48: Ausführungszeitraum: [nach Absprache]
A49: Grundlage: Aufmaß vor Ort. Abrechnung nach tatsächlichem Aufmaß. Nicht aufgeführte Leistungen werden gesondert angeboten.
A51: Mit freundlichen Grüßen
A52: [Name] · [Firma]
A54: Bankverbindung: [Bank] · IBAN: [IBAN] · BIC: [BIC]

Sheet Как пользоваться
A1: Как пользоваться калькулятором
A3: 1. «Ставки» — один раз заполнить жёлтые ячейки: ставки Geselle/Meister (€/ч без НДС), Materialaufschlag, Gemeinkosten, Wagnis, Gewinn (в %), Fahrtkosten €/км, PLZ базы, радиус. MwSt 19 % уже стоит (закон).
A4: 2. «Позиции» — по каждой нужной позиции вписать свои часы на единицу (столбец E) и закупочную цену материала €/ед. (столбец F). Серый столбец G — только ориентир, проверить по своему опыту; в расчёт он не идёт. Внизу 10 пустых строк для своих позиций.
A5: 3. «Расчёт» — для каждого объекта: название объекта (C2), в столбце B выбрать позицию из списка, в D ввести количество, в E — Geselle или Meister. Внизу — км до объекта и число поездок.
A6: Формулы: Lohn = Menge × h × Satz; Material = Menge × Preis × (1 + Aufschlag); Gemeinkosten от Lohn+Material; Wagnis и Gewinn от Selbstkosten; Netto → MwSt → Brutto; Profit € и Marge %.
A7: Если где-то видно «нет ставки» — значит не заполнена ставка, норма часов или цена материала. Нуля вместо цены калькулятор специально не ставит.
A8: 4. «Angebot» — немецкое КП собирается само из листа «Расчёт». Заменить заглушки [Firma], [Adresse], [USt-IdNr], [Kunde], [Zahlungsbedingungen], [IBAN] на свои; срок действия 30 Tage. Печать/экспорт в PDF — из Excel.
A9: 5. Для нового объекта — сохранить копию файла («Сохранить как…»), очистить жёлтые ячейки B, D на листе «Расчёт».
A11: Агент 3 (объёмы, стоимость, прибыль) позже будет читать листы «Ставки» и «Позиции» — поэтому их достаточно заполнить один раз и не переименовывать листы и столбцы. Без ваших ставок агент 3 считает только объёмы, без денег.
A13: Цены в файле не придуманы: все денежные ячейки пустые, кроме НДС 19 %. Отправка КП клиенту — только вами.
A14: Легенда: жёлтая ячейка = вводит владелец; синий шрифт = ввод; голубая заливка = итоги.
